2023-09-29 07:48:18 | ERROR    | __main__:run:126 | An error has been caught in function 'run', process 'MainProcess' (3513), thread 'MainThread' (140628734159744): - {}
Traceback (most recent call last):
  File "/home/runner/work/epic_weekly/epic_weekly/epic/src/claim.py", line 130, in <module>
    asyncio.run(run())
  File "/opt/hostedtoolcache/Python/3.10.13/x64/lib/python3.10/asyncio/runners.py", line 44, in run
    return loop.run_until_complete(main)
  File "/opt/hostedtoolcache/Python/3.10.13/x64/lib/python3.10/asyncio/base_events.py", line 636, in run_until_complete
    self.run_forever()
  File "/opt/hostedtoolcache/Python/3.10.13/x64/lib/python3.10/asyncio/base_events.py", line 603, in run_forever
    self._run_once()
  File "/opt/hostedtoolcache/Python/3.10.13/x64/lib/python3.10/asyncio/base_events.py", line 1909, in _run_once
    handle._run()
  File "/opt/hostedtoolcache/Python/3.10.13/x64/lib/python3.10/asyncio/events.py", line 80, in _run
    self._context.run(self._callback, *self._args)
> File "/home/runner/work/epic_weekly/epic_weekly/epic/src/claim.py", line 126, in run
    await agent.stash()
  File "/home/runner/work/epic_weekly/epic_weekly/epic/src/claim.py", line 120, in stash
    await self.claim_epic_games(context)
  File "/home/runner/work/epic_weekly/epic_weekly/epic/src/claim.py", line 102, in claim_epic_games
    await epic.claim_weekly_games(page, self.promotions)
  File "/home/runner/work/epic_weekly/epic_weekly/epic/src/services/agents/epic_games.py", line 180, in claim_weekly_games
    await expect(cta_btn).to_have_text("View In Cart")
  File "/opt/hostedtoolcache/Python/3.10.13/x64/lib/python3.10/site-packages/playwright/async_api/_generated.py", line 20041, in to_have_text
    await self._impl_obj.to_have_text(
  File "/opt/hostedtoolcache/Python/3.10.13/x64/lib/python3.10/site-packages/playwright/_impl/_assertions.py", line 455, in to_have_text
    await self._expect_impl(
  File "/opt/hostedtoolcache/Python/3.10.13/x64/lib/python3.10/site-packages/playwright/_impl/_assertions.py", line 70, in _expect_impl
    raise AssertionError(f"{out_message}\nActual value: {actual} {log}")
AssertionError: Locator expected to have text 'View In Cart'
Actual value: None 
Call log:
LocatorAssertions.to_have_text with timeout 5000ms
waiting for locator("xpath=//aside//button[@data-testid='add-to-cart-cta-button']")
